Workbook

Sheet Summary
B2: EU Data Analyst Job Market — Summary
B3: Adzuna postings, July 2026 snapshot
B5: Total Postings | C5: % with Salary Data | D5: Median Salary EUR (GB) | E5: Median Salary EUR (FR) | F5: Top Skill (by mentions)
B6: =COUNTA(RawJobs!$D$2:$D$3745) -> 3744 | C6: =COUNT(RawJobs!$G$2:$G$3745)/COUNTA(RawJobs!$D$2:$D$3745) -> 0.73424145 | D6: {=MEDIAN(IF(RawJobs!$D$2:$D$3745="gb",RawJobs!$G$2:$G$3745))} -> 57663.678 | E6: {=MEDIAN(IF(RawJobs!$D$2:$D$3745="fr",RawJobs!$G$2:$G$3745))} -> 43500 | F6: {=INDEX(RawSkills!$B$2:$B$521,MATCH(MAX(COUNTIF(RawSkills!$B$2:$B$521,RawSkills!$B$2:$B$521)),COUNTIF(RawSkills!$B$2:$B$521,RawSkills!$B$2:$B$521),0))} -> sql
B9: Postings by Country
B10: Country | C10: Postings
B11: DE | C11: =COUNTIF(RawJobs!$D$2:$D$3745,B11) -> 277
B12: ES | C12: =COUNTIF(RawJobs!$D$2:$D$3745,B12) -> 68
B13: FR | C13: =COUNTIF(RawJobs!$D$2:$D$3745,B13) -> 1212
B14: GB | C14: =COUNTIF(RawJobs!$D$2:$D$3745,B14) -> 1962
B15: IT | C15: =COUNTIF(RawJobs!$D$2:$D$3745,B15) -> 111
B16: NL | C16: =COUNTIF(RawJobs!$D$2:$D$3745,B16) -> 114

Sheet RawJobs
A1: id | B1: title | C1: company | D1: country | E1: city | F1: created | G1: salary_eur | H1: contract_time | I1: is_junior | J1: is_remote
A2: 5770828727 | B2: Senior IT Business Analyst (m/w/d) | C2: Trianel GmbH | D2: de | E2: Aachen | F2: 2026-06-20 | I2: f | J2: f
A3: 5762643172 | B3: Salesforce Technical Business Analyst (m/w/d) | C3: BELFOR Europe GmbH | D3: de | E3: Duisburg | F3: 2026-06-13 | I3: f | J3: f
A4: 5766906690 | B4: IT Business Analyst Production (m/w/d) | C4: Liebherr-Hydraulikbagger GmbH | D4: de | E4: Kirchdorf | F4: 2026-06-17 | I4: f | J4: f
A5: 5751502749 | B5: SAP Business Analyst SD/LE (m/w/d) | C5: Capri Sun GmbH | D5: de | E5: Deutschland | F5: 2026-06-04 | I5: f | J5: f
A6: 5773180876 | B6: Senior IT-Consultant / Business Analyst Versicherungen (all genders) | C6: adesso SE | D6: de | E6: Düsseldorf | F6: 2026-06-23 | I6: f | J6: f
A7: 5786428751 | B7: Duales Studium Wirtschaftsinformatik B.Sc. – IT-Business-Analyst | C7: Atruvia AG | D7: de | E7: Münster | F7: 2026-07-03 | I7: f | J7: f
A8: 5775008628 | B8: IT Business Analyst Payments (w/m/d) | C8: Aareal Bank AG | D8: de | E8: Wiesbaden | F8: 2026-06-24 | I8: f | J8: f
A9: 5775740862 | B9: IT Business Analyst (gn) - Production | C9: The Quality Group GmbH | D9: de | E9: Hamburg | F9: 2026-06-25 | I9: f | J9: t
A10: 5775009160 | B10: IT Business Analyst - Kontoführung Kernbanksystem (w/m/d) | C10: Aareal Bank AG | D10: de | E10: Wiesbaden | F10: 2026-06-24 | I10: f | J10: f
A11: 5777028058 | B11: Business Analyst | C11: Gattaca PBS | D11: de | E11: München | F11: 2026-06-26 | G11: 77500 | H11: full_time | I11: f | J11: f
A12: 5768047030 | B12: Senior Business Analyst - Trade Life Cycle Management - Commodity Markets (f/m/d) | C12: E.ON Energy Markets GmbH | D12: de | E12: Essen | F12: 2026-06-18 | H12: full_time | I12: f | J12: f
A13: 5785690789 | B13: IT Domain Architect im Bereich Governance Administration (m/w/d) | C13: Liebherr-Aerospace Lindenberg GmbH | D13: de | E13: Lindenberg | F13: 2026-07-02 | I13: f | J13: f
A14: 5768046989 | B14: Engineer as Senior Business Analyst - Coordinate Change Delivery - Risk Management (f/m/d) | C14: E.ON Energy Markets GmbH | D14: de | E14: Essen | F14: 2026-06-18 | H14: full_time | I14: f | J14: f
A15: 5783622139 | B15: IT Business Solution Analyst (m/w/d) | C15: Liebherr-Hausgeräte Ochsenhausen GmbH | D15: de | E15: Ochsenhausen | F15: 2026-07-01 | I15: f | J15: f
A16: 5766895115 | B16: Senior Business Implementation Analyst (f/m/d) | C16: E.ON Energy Markets GmbH | D16: de | E16: Essen | F16: 2026-06-17 | H16: full_time | I16: f | J16: f
A17: 5773180002 | B17: Consultant Digitalisierung - Kreditgeschäft / Wertpapiergeschäft / Projektmanagement (m/w/d) | C17: crossconsulting GmbH | D17: de | E17: Köln | F17: 2026-06-23 | I17: f | J17: f
A18: 5768046997 | B18: Economist as Senior Business Implementation Analyst - Organize Business Testing (f/m/d) | C18: E.ON Energy Markets GmbH | D18: de | E18: Essen | F18: 2026-06-18 | H18: full_time | I18: f | J18: f
A19: 5782063320 | B19: Solution Architect Application Management (m/w/d) | C19: TKMS GmbH | D19: de | E19: Hamburg | F19: 2026-06-30 | I19: f | J19: f
A20: 5772608881 | B20: Application Manager Zahlungsverkehr (m/w/d) | C20: Hanseatic Bank | D20: de | E20: Hamburg | F20: 2026-06-22 | I20: f | J20: f
A21: 5681676555 | B21: Data Analyst (m/w/d) | C21: Topmotive | D21: de | E21: Bargteheide | F21: 2026-03-28 | I21: f | J21: f
A22: 5764839537 | B22: Business Analyst (BillingPlatform) | C22: Darwin Recruitment | D22: de | E22: Berlin | F22: 2026-06-16 | H22: full_time | I22: f | J22: t
A23: 5692242739 | B23: Data Business Analyst | C23: Net2aspire | D23: de | E23: Deutschland | F23: 2026-04-07 | I23: f | J23: t
A24: 5760756783 | B24: Bilingual Business Analyst | C24: TechBiz Global GmbH | D24: de | E24: Deutschland | F24: 2026-06-12 | H24: full_time | I24: f | J24: t
A25: 5120304918 | B25: IT Business Analyst | C25: Micro IT Global | D25: de | E25: Deutschland | F25: 2025-03-31 | I25: f | J25: f
A26: 5773180453 | B26: IT-Systemadministrator - Netzwerk / Sicherheit / Azure (m/w/d) | C26: mbi GmbH | D26: de | E26: Wetzlar | F26: 2026-06-23 | I26: f | J26: f
A27: 5782346188 | B27: Business Analyst – Web Banking | C27: Avaloq | D27: de | E27: Berlin | F27: 2026-06-30 | I27: f | J27: f
A28: 5784961764 | B28: Senior Business Analyst:in im Consulting | C28: viadee Unternehmensberatung AG | D28: de | E28: Hainholz | F28: 2026-07-02 | G28: 72000 | H28: full_time | I28: f | J28: f
A29: 5784961630 | B29: Senior Business Analyst:in Reinsurance | C29: HDI Global | D29: de | E29: Bothfeld | F29: 2026-07-02 | G29: 71000 | H29: full_time | I29: f | J29: f
A30: 5785744507 | B30: Senior Business Analyst (all genders) | C30: SCAYLE | D30: de | E30: Deutschland | F30: 2026-07-02 | I30: f | J30: f
A31: 5785744484 | B31: Senior Business Analyst (all genders) | C31: SCAYLE | D31: de | E31: Deutschland | F31: 2026-07-02 | I31: f | J31: f
A32: 5763829165 | B32: IT Business Analyst (gn) - Production | C32: Bewerbung als IT Business Analyst | D32: de | E32: Hamburg | F32: 2026-06-14 | I32: f | J32: t
A33: 5757612654 | B33: Business Analyst:in (w/m/d) | C33: Ibykus | D33: de | E33: Daberstedt | F33: 2026-06-09 | H33: full_time | I33: f | J33: f
A34: 5752975938 | B34: Business Analyst (m/w/d) | C34: Finanz Informatik GmbH & Co. KG | D34: de | E34: Region Hannover (Kreis) | F34: 2026-06-05 | H34: full_time | I34: f | J34: f
A35: 5727111286 | B35: Business Analyst (m/w/d) | C35: blau direkt | D35: de | E35: Moisling | F35: 2026-05-12 | H35: full_time | I35: f | J35: f
A36: 5727349991 | B36: Business Analyst (m/w/d) | C36: blau direkt | D36: de | E36: Moisling | F36: 2026-05-12 | H36: full_time | I36: f | J36: f
A37: 5727129265 | B37: Business Analyst (m/w/d) | C37: Blueforte | D37: de | E37: Hamburg-Altstadt | F37: 2026-05-12 | H37: full_time | I37: f | J37: f
A38: 5645499831 | B38: Business Analyst (m/w/d) | C38: Striped Giraffe Innovation & Strategy GmbH | D38: de | E38: München | F38: 2026-02-25 | H38: full_time | I38: f | J38: f
A39: 5784960931 | B39: Business Analyst Zahlungsverkehr (all genders) | C39: adesso insurance solutions GmbH | D39: de | E39: Benninghofen | F39: 2026-07-02 | G39: 70000 | H39: full_time | I39: f | J39: f
A40: 5727299297 | B40: Senior Business Analyst (m/w/d) | C40: aixigo | D40: de | E40: Deutschland | F40: 2026-05-12 | H40: full_time | I40: f | J40: f
...

Sheet RawSkills
A1: job_id | B1: skill | C1: country
A2: 5760756783 | B2: english | C2: de
A3: 5773180453 | B3: azure | C3: de
A4: 5784962080 | B4: sql | C4: de
A5: 5779504932 | B5: azure | C5: de
A6: 5768350720 | B6: r | C6: de
A7: 5768350720 | B7: power bi | C7: de
A8: 5768350720 | B8: python | C8: de
A9: 5768350720 | B9: sql | C9: de
A10: 5727331636 | B10: tableau | C10: de
A11: 5727331636 | B11: power bi | C11: de
A12: 5781277991 | B12: power bi | C12: de
A13: 5784961742 | B13: azure | C13: de
... A521: 5777174690 | B521: python | C521: nl

Sheet Pivot_Country
A1: Country | B1: Postings | C1: Median Salary EUR
A2: DE | B2: =COUNTIF(RawJobs!$D$2:$D$3745,A2) -> 277 | C2: {=IFERROR(MEDIAN(IF(RawJobs!$D$2:$D$3745=A2,RawJobs!$G$2:$G$3745)),"n/a")} -> 68000
A3: ES | B3: =COUNTIF(RawJobs!$D$2:$D$3745,A3) -> 68 | C3: {=IFERROR(MEDIAN(IF(RawJobs!$D$2:$D$3745=A3,RawJobs!$G$2:$G$3745)),"n/a")} -> 42500
A4: FR | B4: =COUNTIF(RawJobs!$D$2:$D$3745,A4) -> 1212 | C4: {=IFERROR(MEDIAN(IF(RawJobs!$D$2:$D$3745=A4,RawJobs!$G$2:$G$3745)),"n/a")} -> 43500
A5: GB | B5: =COUNTIF(RawJobs!$D$2:$D$3745,A5) -> 1962 | C5: {=IFERROR(MEDIAN(IF(RawJobs!$D$2:$D$3745=A5,RawJobs!$G$2:$G$3745)),"n/a")} -> 57663.678
A6: IT | B6: =COUNTIF(RawJobs!$D$2:$D$3745,A6) -> 111 | C6: {=IFERROR(MEDIAN(IF(RawJobs!$D$2:$D$3745=A6,RawJobs!$G$2:$G$3745)),"n/a")} -> 32750
A7: NL | B7: =COUNTIF(RawJobs!$D$2:$D$3745,A7) -> 114 | C7: {=IFERROR(MEDIAN(IF(RawJobs!$D$2:$D$3745=A7,RawJobs!$G$2:$G$3745)),"n/a")} -> 52359

Sheet Pivot_Skills
A1: Skill | B1: Mentions
A2: sql | B2: =COUNTIF(RawSkills!$B$2:$B$521,A2) -> 116
A3: power bi | B3: =COUNTIF(RawSkills!$B$2:$B$521,A3) -> 100
A4: python | B4: =COUNTIF(RawSkills!$B$2:$B$521,A4) -> 58
A5: azure | B5: =COUNTIF(RawSkills!$B$2:$B$521,A5) -> 57
A6: excel | B6: =COUNTIF(RawSkills!$B$2:$B$521,A6) -> 41
A7: gcp | B7: =COUNTIF(RawSkills!$B$2:$B$521,A7) -> 26
A8: snowflake | B8: =COUNTIF(RawSkills!$B$2:$B$521,A8) -> 24
A9: tableau | B9: =COUNTIF(RawSkills!$B$2:$B$521,A9) -> 21
A10: aws | B10: =COUNTIF(RawSkills!$B$2:$B$521,A10) -> 12
A11: english | B11: =COUNTIF(RawSkills!$B$2:$B$521,A11) -> 10
A12: sas | B12: =COUNTIF(RawSkills!$B$2:$B$521,A12) -> 10
A13: r | B13: =COUNTIF(RawSkills!$B$2:$B$521,A13) -> 9
... A16: dax | B16: =COUNTIF(RawSkills!$B$2:$B$521,A16) -> 6
